Workbook

Sheet 1 Funnel
B2: 1.4% of sessions end in a purchase, and most are lost before anyone views a product.
B3: 355,592 sessions · 1 Nov 2020 – 31 Jan 2021 · Google Merchandise Store, obfuscated GA4 sample
B5: Sessions | G5: Session conversion rate | L5: Purchasing sessions
B6: =calc!B11 -> 355592 | G6: =calc!B13 -> 0.013619541 | L6: =calc!B12 -> 4843
B8: 30-minute sessions | G8: =calc!B14 -> 95% CI 1.32% – 1.40% | L8: sessions with a purchase event
K10: Each step's conversion from the one before
K12: Step | O12: Conversion | Q12: 95% CI | S12: Skipped previous step
K13: =calc!C2&" → "&LOWER(calc!C3) -> All sessions → viewed a product | O13: =calc!H3 -> 0.215227 | Q13: =TEXT(calc!I3,"0.0%")&" – "&TEXT(calc!J3,"0.0%") -> 21.4% – 21.7% | S13: =calc!K3 -> 0
K14: =calc!C3&" → "&LOWER(calc!C4) -> Viewed a product → added to cart | O14: =calc!H4 -> 0.19716985 | Q14: =TEXT(calc!I4,"0.0%")&" – "&TEXT(calc!J4,"0.0%") -> 19.4% – 20.0% | S14: =calc!K4 -> 0.0010591818
K15: =calc!C4&" → "&LOWER(calc!C5) -> Added to cart → began checkout | O15: =calc!H5 -> 0.39401562 | Q15: =TEXT(calc!I5,"0.0%")&" – "&TEXT(calc!J5,"0.0%") -> 38.6% – 40.2% | S15: =calc!K5 -> 0.46199042
K16: =calc!C5&" → "&LOWER(calc!C6) -> Began checkout → added shipping info | O16: =calc!H6 -> 0.99981922 | Q16: =TEXT(calc!I6,"0.0%")&" – "&TEXT(calc!J6,"0.0%") -> 99.9% – 100.0% | S16: =calc!K6 -> 9.0399566e-05
K17: =calc!C6&" → "&LOWER(calc!C7) -> Added shipping info → added payment info | O17: =calc!H7 -> 0.61318026 | Q17: =TEXT(calc!I7,"0.0%")&" – "&TEXT(calc!J7,"0.0%") -> 60.4% – 62.2% | S17: =calc!K7 -> 0.00044208665
K18: =calc!C7&" → "&LOWER(calc!C8) -> Added payment info → purchased | O18: =calc!H8 -> 0.71323313 | Q18: =TEXT(calc!I8,"0.0%")&" – "&TEXT(calc!J8,"0.0%") -> 70.2% – 72.4% | S18: =calc!K8 -> 0.00061945075
B36: Base: 355,592 30-minute sessions, not GA4's own sessions. A session reaches a step if it contains the event. Intervals: 95% Wilson. Source: dbt model rpt_funnel.

Sheet 2 Leaks
B2: Referral sessions convert above the rest; organic, cpc and 'other' convert below.
B3: 355,592 sessions · 1 Nov 2020 – 31 Jan 2021 · Google Merchandise Store, obfuscated GA4 sample
B5: Funnel step | C5: purchase
B7: ="Segments whose """&LOWER(_xlfn.XLOOKUP($C$5,calc!$B$2:$B$8,calc!$C$2:$C$8))&""" rate differs from the rest of sessions" -> Segments whose "purchased" rate differs from the rest of sessions
K9: Rates and gaps at the selected step
K10: Group | L10: Segment | N10: Sessions | O10: Rate | P10: 95% CI | R10: Gap vs rest | S10: 95% CI
K11: =calc!AD2 -> Device | L11: =calc!AE2 -> desktop | N11: =calc!T2 -> 206354 | O11: =calc!U2 -> 0.013268461 | P11: =TEXT(calc!V2,"0.00%")&" – "&TEXT(calc!W2,"0.00%") -> 1.28% – 1.38% | R11: =calc!X2*100 -> -0.083652567 | S11: =TEXT(calc!Y2*100,"+0.00;-0.00")&" to "&TEXT(calc!Z2*100,"+0.00;-0.00") -> -0.16 to -0.01
K12: =calc!AD3 | L12: =calc!AE3 -> mobile | N12: =calc!T3 -> 141352 | O12: =calc!U3 -> 0.014177373 | P12: =TEXT(calc!V3,"0.00%")&" – "&TEXT(calc!W3,"0.00%") -> 1.36% – 1.48% | R12: =calc!X3*100 -> 0.092587915 | S12: =TEXT(calc!Y3*100,"+0.00;-0.00")&" to "&TEXT(calc!Z3*100,"+0.00;-0.00") -> +0.01 to +0.17
K13: =calc!AD4 | L13: =calc!AE4 -> tablet | N13: =calc!T4 -> 7886 | O13: =calc!U4 -> 0.012807507 | P13: =TEXT(calc!V4,"0.00%")&" – "&TEXT(calc!W4,"0.00%") -> 1.06% – 1.55% | R13: =calc!X4*100 -> -0.083045153 | S13: =TEXT(calc!Y4*100,"+0.00;-0.00")&" to "&TEXT(calc!Z4*100,"+0.00;-0.00") -> -0.31 to +0.19
K14: =calc!AD5 -> Continent | L14: =calc!AE5 -> americas | N14: =calc!T5 -> 196608 | O14: =calc!U5 -> 0.013809204 | P14: =TEXT(calc!V5,"0.00%")&" – "&TEXT(calc!W5,"0.00%") -> 1.33% – 1.43% | R14: =calc!X5*100 -> 0.042420939 | S14: =TEXT(calc!Y5*100,"+0.00;-0.00")&" to "&TEXT(calc!Z5*100,"+0.00;-0.00") -> -0.03 to +0.12
K15: =calc!AD6 | L15: =calc!AE6 -> asia | N15: =calc!T6 -> 84481 | O15: =calc!U6 -> 0.013316604 | P15: =TEXT(calc!V6,"0.00%")&" – "&TEXT(calc!W6,"0.00%") -> 1.26% – 1.41% | R15: =calc!X6*100 -> -0.039733631 | S15: =TEXT(calc!Y6*100,"+0.00;-0.00")&" to "&TEXT(calc!Z6*100,"+0.00;-0.00") -> -0.13 to +0.05
K16: =calc!AD7 | L16: =calc!AE7 -> europe | N16: =calc!T7 -> 66291 | O16: =calc!U7 -> 0.013546334 | P16: =TEXT(calc!V7,"0.00%")&" – "&TEXT(calc!W7,"0.00%") -> 1.27% – 1.45% | R16: =calc!X7*100 -> -0.0089982911 | S16: =TEXT(calc!Y7*100,"+0.00;-0.00")&" to "&TEXT(calc!Z7*100,"+0.00;-0.00") -> -0.10 to +0.09
K17: =calc!AD8 | L17: =calc!AE8 -> oceania | N17: =calc!T8 -> 3745 | O17: =calc!U8 -> 0.013618158 | P17: =TEXT(calc!V8,"0.00%")&" – "&TEXT(calc!W8,"0.00%") -> 1.04% – 1.79% | R17: =calc!X8*100 -> -0.00013986842 | S17: =TEXT(calc!Y8*100,"+0.00;-0.00")&" to "&TEXT(calc!Z8*100,"+0.00;-0.00") -> -0.33 to +0.43
K18: =calc!AD9 | L18: =calc!AE9 -> africa | N18: =calc!T9 -> 3664 | O18: =calc!U9 -> 0.011735808 | P18: =TEXT(calc!V9,"0.00%")&" – "&TEXT(calc!W9,"0.00%") -> 0.87% – 1.58% | R18: =calc!X9*100 -> -0.19033456 | S18: =TEXT(calc!Y9*100,"+0.00;-0.00")&" to "&TEXT(calc!Z9*100,"+0.00;-0.00") -> -0.49 to +0.21
K19: =calc!AD10 | L19: =calc!AE10 -> unknown | N19: =calc!T10 -> 803 | O19: =calc!U10 -> 0.01369863 | P19: =TEXT(calc!V10,"0.00%")&" – "&TEXT(calc!W10,"0.00%") -> 0.77% – 2.44% | R19: =calc!X10*100 -> 0.0079267643 | S19: =TEXT(calc!Y10*100,"+0.00;-0.00")&" to "&TEXT(calc!Z10*100,"+0.00;-0.00") -> -0.60 to +1.07
K20: =calc!AD11 -> Channel | L20: =calc!AE11 -> organic | N20: =calc!T11 -> 121780 | O20: =calc!U11 -> 0.011151256 | P20: =TEXT(calc!V11,"0.00%")&" – "&TEXT(calc!W11,"0.00%") -> 1.06% – 1.18% | R20: =calc!X11*100 -> -0.37538811 | S20: =TEXT(calc!Y11*100,"+0.00;-0.00")&" to "&TEXT(calc!Z11*100,"+0.00;-0.00") -> -0.45 to -0.30
K21: =calc!AD12 | L21: =calc!AE12 -> direct | N21: =calc!T12 -> 82493 | O21: =calc!U12 -> 0.013055653 | P21: =TEXT(calc!V12,"0.00%")&" – "&TEXT(calc!W12,"0.00%") -> 1.23% – 1.39% | R21: =calc!X12*100 -> -0.073421787 | S21: =TEXT(calc!Y12*100,"+0.00;-0.00")&" to "&TEXT(calc!Z12*100,"+0.00;-0.00") -> -0.16 to +0.02
K22: =calc!AD13 | L22: =calc!AE13 -> referral | N22: =calc!T13 -> 62331 | O22: =calc!U13 -> 0.01684555 | P22: =TEXT(calc!V13,"0.00%")&" – "&TEXT(calc!W13,"0.00%") -> 1.59% – 1.79% | R22: =calc!X13*100 -> 0.39116792 | S22: =TEXT(calc!Y13*100,"+0.00;-0.00")&" to "&TEXT(calc!Z13*100,"+0.00;-0.00") -> +0.28 to +0.50
... K25: =calc!AD16 | L25: =calc!AE16 -> unknown | N25: =calc!T16 -> 21651 | O25: =calc!U16 -> 0.031961572 | P25: =TEXT(calc!V16,"0.00%")&" – "&TEXT(calc!W16,"0.00%") -> 2.97% – 3.44% | R25: =calc!X16*100 -> 1.9531233 | S25: =TEXT(calc!Y16*100,"+0.00;-0.00")&" to "&TEXT(calc!Z16*100,"+0.00;-0.00") -> +1.72 to +2.20
B36: Base: 355,592 30-minute sessions. Gap = segment's rate minus all other sessions' rate (percentage points), 95% Newcombe interval. Channel = the session's first-event medium. Association, not cause. Source: dbt model rpt_funnel.

Sheet 3 Time & Products
B2: Conversion peaked at 2.0% in early December and fell to 0.6% in the first week of January.
B3: 355,592 sessions · 1 Nov 2020 – 31 Jan 2021 · Google Merchandise Store, obfuscated GA4 sample
B36: Base: 30-minute sessions by ISO week (Mon start); the one-day week of 26 Oct is left out. Intervals: 95% Wilson. Source: dbt models rpt_funnel_weekly, rpt_product_funnel.

Sheet d_product
A1: item_category | B1: category_sort | C1: sessions_viewed | D1: sessions_viewed_and_carted | E1: sessions_viewed_and_purchased | F1: sessions_purchased | G1: units_purchased | H1: item_revenue_in_usd | I1: view_to_cart_rate | J1: view_to_cart_rate_lower | K1: view_to_cart_rate_upper | L1: view_to_purchase_rate | M1: view_to_purchase_rate_lower | N1: view_to_purchase_rate_upper | O1: is_thin_cell | P1: reach_err_minus | Q1: v2p_err_minus | R1: v2p_err_plus
A2: home/black lives matter/ | B2: 34 | C2: 26 | D2: 3 | E2: 1 | F2: 2 | G2: 2 | H2: 104 | I2: 0.11538462 | J2: 0.040032446 | K2: 0.28975903 | L2: 0.038461538 | M2: 0.0068219849 | N2: 0.18892779 | O2: 1 | Q2: =tProduct[[#This Row],[view_to_purchase_rate]]-tProduct[[#This Row],[view_to_purchase_rate_lower]] -> 0.031639554 | R2: =tProduct[[#This Row],[view_to_purchase_rate_upper]]-tProduct[[#This Row],[view_to_purchase_rate]] -> 0.15046625
A3: home/stationery/notebooks/ | B3: 16 | C3: 5666 | D3: 1526 | E3: 306 | F3: 332 | G3: 791 | H3: 8253 | I3: 0.2693258 | J3: 0.25793418 | K3: 0.28103 | L3: 0.054006354 | M3: 0.04841736 | N3: 0.060199691 | O3: 0 | Q3: =tProduct[[#This Row],[view_to_purchase_rate]]-tProduct[[#This Row],[view_to_purchase_rate_lower]] -> 0.0055889937 | R3: =tProduct[[#This Row],[view_to_purchase_rate_upper]]-tProduct[[#This Row],[view_to_purchase_rate]] -> 0.0061933373
A4: home/shop by brand/youtube/ | B4: 4 | C4: 18021 | D4: 4834 | E4: 237 | F4: 252 | G4: 619 | H4: 6151 | I4: 0.26824261 | J4: 0.26182396 | K4: 0.27476003 | L4: 0.013151323 | M4: 0.011588732 | N4: 0.01492143 | O4: 0 | Q4: =tProduct[[#This Row],[view_to_purchase_rate]]-tProduct[[#This Row],[view_to_purchase_rate_lower]] -> 0.0015625915 | R4: =tProduct[[#This Row],[view_to_purchase_rate_upper]]-tProduct[[#This Row],[view_to_purchase_rate]] -> 0.0017701061
A5: campus collection | B5: 29 | C5: 206 | D5: 71 | E5: 7 | F5: 8 | G5: 9 | H5: 134 | I5: 0.34466019 | J5: 0.28313806 | K5: 0.41186978 | L5: 0.033980583 | M5: 0.016555878 | N5: 0.06846764 | O5: 0 | Q5: =tProduct[[#This Row],[view_to_purchase_rate]]-tProduct[[#This Row],[view_to_purchase_rate_lower]] -> 0.017424705 | R5: =tProduct[[#This Row],[view_to_purchase_rate_upper]]-tProduct[[#This Row],[view_to_purchase_rate]] -> 0.034487057
A6: home/new/ | B6: 5 | C6: 17171 | D6: 3693 | E6: 297 | F6: 319 | G6: 486 | H6: 8519 | I6: 0.21507192 | J6: 0.20899051 | K6: 0.22128079 | L6: 0.017296605 | M6: 0.015451768 | N6: 0.019357372 | O6: 0 | Q6: =tProduct[[#This Row],[view_to_purchase_rate]]-tProduct[[#This Row],[view_to_purchase_rate_lower]] -> 0.0018448365 | R6: =tProduct[[#This Row],[view_to_purchase_rate_upper]]-tProduct[[#This Row],[view_to_purchase_rate]] -> 0.0020607669
A7: home/apparel/kids/ | B7: 15 | C7: 5994 | D7: 1321 | E7: 377 | F7: 391 | G7: 666 | H7: 13447 | I7: 0.22038705 | J7: 0.21007442 | K7: 0.23105785 | L7: 0.06289623 | M7: 0.05702573 | N7: 0.069326636 | O7: 0 | Q7: =tProduct[[#This Row],[view_to_purchase_rate]]-tProduct[[#This Row],[view_to_purchase_rate_lower]] -> 0.0058704997 | R7: =tProduct[[#This Row],[view_to_purchase_rate_upper]]-tProduct[[#This Row],[view_to_purchase_rate]] -> 0.0064304066
A8: accessories/ | B8: 27 | C8: 309 | D8: 88 | E8: 31 | F8: 41 | G8: 61 | H8: 288 | I8: 0.28478964 | J8: 0.23735156 | K8: 0.33751297 | L8: 0.10032362 | M8: 0.071580256 | N8: 0.13888245 | O8: 0 | Q8: =tProduct[[#This Row],[view_to_purchase_rate]]-tProduct[[#This Row],[view_to_purchase_rate_lower]] -> 0.028743368 | R8: =tProduct[[#This Row],[view_to_purchase_rate_upper]]-tProduct[[#This Row],[view_to_purchase_rate]] -> 0.038558822
A9: home/apparel/ | B9: 9 | C9: 10314 | D9: 2362 | E9: 302 | F9: 326 | G9: 530 | H9: 7749 | I9: 0.22900911 | J9: 0.22100155 | K9: 0.23721847 | L9: 0.029280589 | M9: 0.026198079 | N9: 0.032713609 | O9: 0 | Q9: =tProduct[[#This Row],[view_to_purchase_rate]]-tProduct[[#This Row],[view_to_purchase_rate_lower]] -> 0.0030825105 | R9: =tProduct[[#This Row],[view_to_purchase_rate_upper]]-tProduct[[#This Row],[view_to_purchase_rate]] -> 0.0034330197
A10: home/apparel/hats/ | B10: 2 | C10: 22236 | D10: 5615 | E10: 580 | F10: 621 | G10: 1100 | H10: 15148 | I10: 0.25251844 | J10: 0.24685112 | K10: 0.25827125 | L10: 0.026083828 | M10: 0.024069355 | N10: 0.028262019 | O10: 0 | Q10: =tProduct[[#This Row],[view_to_purchase_rate]]-tProduct[[#This Row],[view_to_purchase_rate_lower]] -> 0.0020144731 | R10: =tProduct[[#This Row],[view_to_purchase_rate_upper]]-tProduct[[#This Row],[view_to_purchase_rate]] -> 0.0021781909
A11: lifestyle/small goods/ | B11: 11 | C11: 9646 | D11: 2066 | E11: 305 | F11: 342 | G11: 675 | H11: 6492 | I11: 0.21418204 | J11: 0.20610962 | K11: 0.22248203 | L11: 0.031619324 | M11: 0.028309503 | N11: 0.035302056 | O11: 0 | Q11: =tProduct[[#This Row],[view_to_purchase_rate]]-tProduct[[#This Row],[view_to_purchase_rate_lower]] -> 0.0033098214 | R11: =tProduct[[#This Row],[view_to_purchase_rate_upper]]-tProduct[[#This Row],[view_to_purchase_rate]] -> 0.0036827322
A12: bags | B12: 24 | C12: 2233 | D12: 225 | E12: 72 | F12: 82 | G12: 140 | H12: 6834 | I12: 0.10076131 | J12: 0.088953853 | K12: 0.11394003 | L12: 0.032243618 | M12: 0.02568257 | N12: 0.040411277 | O12: 0 | Q12: =tProduct[[#This Row],[view_to_purchase_rate]]-tProduct[[#This Row],[view_to_purchase_rate_lower]] -> 0.006561048 | R12: =tProduct[[#This Row],[view_to_purchase_rate_upper]]-tProduct[[#This Row],[view_to_purchase_rate]] -> 0.0081676588
A13: home/stationery/stickers/ | B13: 22 | C13: 2512 | D13: 797 | E13: 117 | F13: 131 | G13: 304 | H13: 456 | I13: 0.31727707 | J13: 0.29936748 | K13: 0.33574467 | L13: 0.046576433 | M13: 0.039005305 | N13: 0.055532234 | O13: 0 | Q13: =tProduct[[#This Row],[view_to_purchase_rate]]-tProduct[[#This Row],[view_to_purchase_rate_lower]] -> 0.0075711284 | R13: =tProduct[[#This Row],[view_to_purchase_rate_upper]]-tProduct[[#This Row],[view_to_purchase_rate]] -> 0.0089558007
... A36: small goods | B36: 19 | C36: 3730 | D36: 568 | E36: 310 | F36: 361 | G36: 570 | H36: 9638 | I36: 0.15227882 | J36: 0.14110666 | K36: 0.16416646 | L36: 0.08310992 | M36: 0.074674123 | N36: 0.092403528 | O36: 0 | Q36: =tProduct[[#This Row],[view_to_purchase_rate]]-tProduct[[#This Row],[view_to_purchase_rate_lower]] -> 0.0084357966 | R36: =tProduct[[#This Row],[view_to_purchase_rate_upper]]-tProduct[[#This Row],[view_to_purchase_rate]] -> 0.0092936081

Sheet d_weekly
A1: week_start | B1: week_label | C1: week_sort | D1: days_in_week | E1: is_partial_week | F1: sessions | G1: sessions_with_view_item | H1: sessions_with_add_to_cart | I1: sessions_with_begin_checkout | J1: sessions_with_purchase | K1: session_conversion_rate | L1: session_conversion_rate_lower | M1: session_conversion_rate_upper | N1: cr_err_minus | O1: cr_err_plus
A2: 44200 | B2: 04 Jan | C2: 11 | D2: 7 | E2: 0 | F2: 28756 | G2: 4413 | H2: 954 | I2: 344 | J2: 162 | K2: 0.0056336069 | L2: 0.0048321124 | M2: 0.0065671667 | N2: =tWeekly[[#This Row],[session_conversion_rate]]-tWeekly[[#This Row],[session_conversion_rate_lower]] -> 0.0008014945 | O2: =tWeekly[[#This Row],[session_conversion_rate_upper]]-tWeekly[[#This Row],[session_conversion_rate]] -> 0.00093355978
A3: 44137 | B3: 02 Nov | C3: 2 | D3: 7 | E3: 0 | F3: 24630 | G3: 5496 | H3: 0 | I3: 883 | J3: 249 | K3: 0.010109622 | L3: 0.0089344515 | M3: 0.011437583 | N3: =tWeekly[[#This Row],[session_conversion_rate]]-tWeekly[[#This Row],[session_conversion_rate_lower]] -> 0.0011751709 | O3: =tWeekly[[#This Row],[session_conversion_rate_upper]]-tWeekly[[#This Row],[session_conversion_rate]] -> 0.0013279602
A4: 44179 | B4: 14 Dec | C4: 8 | D4: 7 | E4: 0 | F4: 32973 | G4: 7029 | H4: 2082 | I4: 1010 | J4: 547 | K4: 0.016589331 | L4: 0.015265934 | M4: 0.018025352 | N4: =tWeekly[[#This Row],[session_conversion_rate]]-tWeekly[[#This Row],[session_conversion_rate_lower]] -> 0.0013233967 | O4: =tWeekly[[#This Row],[session_conversion_rate_upper]]-tWeekly[[#This Row],[session_conversion_rate]] -> 0.0014360213
A5: 44130 | B5: 26 Oct | C5: 1 | D5: 1 | E5: 1 | F5: 2592 | G5: 535 | H5: 1 | I5: 94 | J5: 13 | K5: 0.0050154321 | L5: 0.0029334322 | M5: 0.0085624389 | N5: =tWeekly[[#This Row],[session_conversion_rate]]-tWeekly[[#This Row],[session_conversion_rate_lower]] -> 0.0020819999 | O5: =tWeekly[[#This Row],[session_conversion_rate_upper]]-tWeekly[[#This Row],[session_conversion_rate]] -> 0.0035470068
A6: 44151 | B6: 16 Nov | C6: 4 | D6: 7 | E6: 0 | F6: 25488 | G6: 6577 | H6: 531 | I6: 1043 | J6: 373 | K6: 0.014634338 | L6: 0.013231546 | M6: 0.016183412 | N6: =tWeekly[[#This Row],[session_conversion_rate]]-tWeekly[[#This Row],[session_conversion_rate_lower]] -> 0.0014027916 | O6: =tWeekly[[#This Row],[session_conversion_rate_upper]]-tWeekly[[#This Row],[session_conversion_rate]] -> 0.0015490746
A7: 44207 | B7: 11 Jan | C7: 12 | D7: 7 | E7: 0 | F7: 27384 | G7: 4812 | H7: 1082 | I7: 454 | J7: 227 | K7: 0.0082895121 | L7: 0.0072824609 | M7: 0.0094344995 | N7: =tWeekly[[#This Row],[session_conversion_rate]]-tWeekly[[#This Row],[session_conversion_rate_lower]] -> 0.0010070513 | O7: =tWeekly[[#This Row],[session_conversion_rate_upper]]-tWeekly[[#This Row],[session_conversion_rate]] -> 0.0011449873
A8: 44165 | B8: 30 Nov | C8: 6 | D8: 7 | E8: 0 | F8: 30633 | G8: 7724 | H8: 2600 | I8: 1413 | J8: 590 | K8: 0.019260275 | L8: 0.017780389 | M8: 0.020860718 | N8: =tWeekly[[#This Row],[session_conversion_rate]]-tWeekly[[#This Row],[session_conversion_rate_lower]] -> 0.001479886 | O8: =tWeekly[[#This Row],[session_conversion_rate_upper]]-tWeekly[[#This Row],[session_conversion_rate]] -> 0.0016004429
A9: 44221 | B9: 25 Jan | C9: 14 | D9: 7 | E9: 0 | F9: 26065 | G9: 6165 | H9: 1082 | I9: 578 | J9: 311 | K9: 0.011931709 | L9: 0.010683619 | M9: 0.013323641 | N9: =tWeekly[[#This Row],[session_conversion_rate]]-tWeekly[[#This Row],[session_conversion_rate_lower]] -> 0.0012480903 | O9: =tWeekly[[#This Row],[session_conversion_rate_upper]]-tWeekly[[#This Row],[session_conversion_rate]] -> 0.0013919321
A10: 44144 | B10: 09 Nov | C10: 3 | D10: 7 | E10: 0 | F10: 22177 | G10: 5526 | H10: 0 | I10: 1039 | J10: 341 | K10: 0.015376291 | L10: 0.013838775 | M10: 0.017081668 | N10: =tWeekly[[#This Row],[session_conversion_rate]]-tWeekly[[#This Row],[session_conversion_rate_lower]] -> 0.0015375154 | O10: =tWeekly[[#This Row],[session_conversion_rate_upper]]-tWeekly[[#This Row],[session_conversion_rate]] -> 0.0017053776
A11: 44172 | B11: 07 Dec | C11: 7 | D11: 7 | E11: 0 | F11: 38220 | G11: 8164 | H11: 2701 | I11: 1572 | J11: 770 | K11: 0.02014652 | L11: 0.018785404 | M11: 0.021604085 | N11: =tWeekly[[#This Row],[session_conversion_rate]]-tWeekly[[#This Row],[session_conversion_rate_lower]] -> 0.0013611157 | O11: =tWeekly[[#This Row],[session_conversion_rate_upper]]-tWeekly[[#This Row],[session_conversion_rate]] -> 0.0014575653
A12: 44214 | B12: 18 Jan | C12: 13 | D12: 7 | E12: 0 | F12: 27142 | G12: 6441 | H12: 1199 | I12: 681 | J12: 375 | K12: 0.013816226 | L12: 0.012494746 | M12: 0.015275307 | N12: =tWeekly[[#This Row],[session_conversion_rate]]-tWeekly[[#This Row],[session_conversion_rate_lower]] -> 0.00132148 | O12: =tWeekly[[#This Row],[session_conversion_rate_upper]]-tWeekly[[#This Row],[session_conversion_rate]] -> 0.0014590815
A13: 44158 | B13: 23 Nov | C13: 5 | D13: 7 | E13: 0 | F13: 27376 | G13: 6468 | H13: 1240 | I13: 1276 | J13: 514 | K13: 0.01877557 | L13: 0.017233939 | M13: 0.020452235 | N13: =tWeekly[[#This Row],[session_conversion_rate]]-tWeekly[[#This Row],[session_conversion_rate_lower]] -> 0.001541631 | O13: =tWeekly[[#This Row],[session_conversion_rate_upper]]-tWeekly[[#This Row],[session_conversion_rate]] -> 0.001676665
... A15: 44193 | B15: 28 Dec | C15: 10 | D15: 7 | E15: 0 | F15: 20268 | G15: 3096 | H15: 653 | I15: 261 | J15: 138 | K15: 0.0068087626 | L15: 0.005766355 | M15: 0.008038087 | N15: =tWeekly[[#This Row],[session_conversion_rate]]-tWeekly[[#This Row],[session_conversion_rate_lower]] -> 0.0010424076 | O15: =tWeekly[[#This Row],[session_conversion_rate_upper]]-tWeekly[[#This Row],[session_conversion_rate]] -> 0.0012293244

Sheet d_funnel
A1: segment_type | B1: segment_type_sort | C1: segment_value | D1: segment_sort | E1: step | F1: step_sort | G1: segment_sessions | H1: sessions_reached | I1: prev_step_sessions | J1: reached_from_prev | K1: reach_rate | L1: reach_rate_lower | M1: reach_rate_upper | N1: step_conversion | O1: step_conversion_lower | P1: step_conversion_upper | Q1: skipped_prev_share | R1: gap_vs_rest | S1: gap_vs_rest_lower | T1: gap_vs_rest_upper | U1: is_thin_segment | V1: is_thin_step | W1: reach_err_minus | X1: reach_err_plus | Y1: conv_err_minus | Z1: conv_err_plus | AA1: gap_err_minus | AB1: gap_err_plus
A2: channel | B2: 4 | C2: cpc | D2: 6 | E2: purchase | F2: 7 | G2: 15548 | H2: 152 | I2: 214 | J2: 152 | K2: 0.009776177 | L2: 0.0083461812 | M2: 0.011448353 | N2: 0.71028037 | O2: 0.64621868 | P2: 0.76692582 | Q2: 0 | R2: -0.0040190966 | S2: -0.0055033298 | T2: -0.0023028159 | U2: 0 | V2: 0 | W2: =tFunnel[[#This Row],[reach_rate]] -tFunnel[[#This Row],[reach_rate_lower]] -> 0.0014299958 | X2: =tFunnel[[#This Row],[reach_rate_upper]]-tFunnel[[#This Row],[reach_rate]] -> 0.0016721761 | Y2: =tFunnel[[#This Row],[step_conversion]]-tFunnel[[#This Row],[step_conversion_lower]] -> 0.064061693 | Z2: =tFunnel[[#This Row],[step_conversion_upper]]-tFunnel[[#This Row],[step_conversion]] -> 0.056645442 | AA2: =tFunnel[[#This Row],[gap_vs_rest]]-tFunnel[[#This Row],[gap_vs_rest_lower]] -> 0.0014842332 | AB2: =tFunnel[[#This Row],[gap_vs_rest_upper]]-tFunnel[[#This Row],[gap_vs_rest]] -> 0.0017162806
A3: channel | B3: 4 | C3: unknown | D3: 99 | E3: purchase | F3: 7 | G3: 21651 | H3: 692 | I3: 956 | J3: 691 | K3: 0.031961572 | L3: 0.029700352 | M3: 0.034388848 | N3: 0.72280335 | O3: 0.69358027 | P3: 0.75024302 | Q3: 0.0014450867 | R3: 0.019531233 | S3: 0.017238067 | T3: 0.021986579 | U3: 0 | V3: 0 | W3: =tFunnel[[#This Row],[reach_rate]] -tFunnel[[#This Row],[reach_rate_lower]] -> 0.0022612202 | X3: =tFunnel[[#This Row],[reach_rate_upper]]-tFunnel[[#This Row],[reach_rate]] -> 0.0024272754 | Y3: =tFunnel[[#This Row],[step_conversion]]-tFunnel[[#This Row],[step_conversion_lower]] -> 0.029223072 | Z3: =tFunnel[[#This Row],[step_conversion_upper]]-tFunnel[[#This Row],[step_conversion]] -> 0.027439674 | AA3: =tFunnel[[#This Row],[gap_vs_rest]]-tFunnel[[#This Row],[gap_vs_rest_lower]] -> 0.0022931654 | AB3: =tFunnel[[#This Row],[gap_vs_rest_upper]]-tFunnel[[#This Row],[gap_vs_rest]] -> 0.0024553463
A4: channel | B4: 4 | C4: other | D4: 4 | E4: purchase | F4: 7 | G4: 51789 | H4: 514 | I4: 727 | J4: 514 | K4: 0.0099248875 | L4: 0.0091067533 | M4: 0.010815719 | N4: 0.70701513 | O4: 0.67291215 | P4: 0.73894188 | Q4: 0 | R4: -0.004324478 | S4: -0.005247627 | T4: -0.003341581 | U4: 0 | V4: 0 | W4: =tFunnel[[#This Row],[reach_rate]] -tFunnel[[#This Row],[reach_rate_lower]] -> 0.00081813421 | X4: =tFunnel[[#This Row],[reach_rate_upper]]-tFunnel[[#This Row],[reach_rate]] -> 0.00089083165 | Y4: =tFunnel[[#This Row],[step_conversion]]-tFunnel[[#This Row],[step_conversion_lower]] -> 0.034102976 | Z4: =tFunnel[[#This Row],[step_conversion_upper]]-tFunnel[[#This Row],[step_conversion]] -> 0.031926744 | AA4: =tFunnel[[#This Row],[gap_vs_rest]]-tFunnel[[#This Row],[gap_vs_rest_lower]] -> 0.00092314895 | AB4: =tFunnel[[#This Row],[gap_vs_rest_upper]]-tFunnel[[#This Row],[gap_vs_rest]] -> 0.00098289697
A5: channel | B5: 4 | C5: referral | D5: 3 | E5: purchase | F5: 7 | G5: 62331 | H5: 1050 | I5: 1455 | J5: 1050 | K5: 0.01684555 | L5: 0.01586462 | M5: 0.017886031 | N5: 0.72164948 | O5: 0.69805973 | P5: 0.74407193 | Q5: 0 | R5: 0.0039116792 | S5: 0.0028464309 | T5: 0.0050273365 | U5: 0 | V5: 0 | W5: =tFunnel[[#This Row],[reach_rate]] -tFunnel[[#This Row],[reach_rate_lower]] -> 0.00098093065 | X5: =tFunnel[[#This Row],[reach_rate_upper]]-tFunnel[[#This Row],[reach_rate]] -> 0.0010404806 | Y5: =tFunnel[[#This Row],[step_conversion]]-tFunnel[[#This Row],[step_conversion_lower]] -> 0.023589754 | Z5: =tFunnel[[#This Row],[step_conversion_upper]]-tFunnel[[#This Row],[step_conversion]] -> 0.022422448 | AA5: =tFunnel[[#This Row],[gap_vs_rest]]-tFunnel[[#This Row],[gap_vs_rest_lower]] -> 0.0010652482 | AB5: =tFunnel[[#This Row],[gap_vs_rest_upper]]-tFunnel[[#This Row],[gap_vs_rest]] -> 0.0011156573
A6: channel | B6: 4 | C6: direct | D6: 2 | E6: purchase | F6: 7 | G6: 82493 | H6: 1077 | I6: 1491 | J6: 1076 | K6: 0.013055653 | L6: 0.0123034 | M6: 0.013853255 | N6: 0.72166331 | O6: 0.69836682 | P6: 0.74382055 | Q6: 0.00092850511 | R6: -0.00073421787 | S6: -0.0016078622 | T6: 0.00017218858 | U6: 0 | V6: 0 | W6: =tFunnel[[#This Row],[reach_rate]] -tFunnel[[#This Row],[reach_rate_lower]] -> 0.00075225295 | X6: =tFunnel[[#This Row],[reach_rate_upper]]-tFunnel[[#This Row],[reach_rate]] -> 0.000797602 | Y6: =tFunnel[[#This Row],[step_conversion]]-tFunnel[[#This Row],[step_conversion_lower]] -> 0.023296497 | Z6: =tFunnel[[#This Row],[step_conversion_upper]]-tFunnel[[#This Row],[step_conversion]] -> 0.022157232 | AA6: =tFunnel[[#This Row],[gap_vs_rest]]-tFunnel[[#This Row],[gap_vs_rest_lower]] -> 0.00087364432 | AB6: =tFunnel[[#This Row],[gap_vs_rest_upper]]-tFunnel[[#This Row],[gap_vs_rest]] -> 0.00090640644
A7: channel | B7: 4 | C7: organic | D7: 1 | E7: purchase | F7: 7 | G7: 121780 | H7: 1358 | I7: 1943 | J7: 1357 | K7: 0.011151256 | L7: 0.010576708 | M7: 0.011756644 | N7: 0.69840453 | O7: 0.6776225 | P7: 0.71840359 | Q7: 0.00073637703 | R7: -0.0037538811 | S7: -0.0045149956 | T7: -0.0029792686 | U7: 0 | V7: 0 | W7: =tFunnel[[#This Row],[reach_rate]] -tFunnel[[#This Row],[reach_rate_lower]] -> 0.00057454816 | X7: =tFunnel[[#This Row],[reach_rate_upper]]-tFunnel[[#This Row],[reach_rate]] -> 0.00060538792 | Y7: =tFunnel[[#This Row],[step_conversion]]-tFunnel[[#This Row],[step_conversion_lower]] -> 0.02078203 | Z7: =tFunnel[[#This Row],[step_conversion_upper]]-tFunnel[[#This Row],[step_conversion]] -> 0.019999056 | AA7: =tFunnel[[#This Row],[gap_vs_rest]]-tFunnel[[#This Row],[gap_vs_rest_lower]] -> 0.00076111448 | AB7: =tFunnel[[#This Row],[gap_vs_rest_upper]]-tFunnel[[#This Row],[gap_vs_rest]] -> 0.00077461246
A8: continent | B8: 3 | C8: unknown | D8: 99 | E8: purchase | F8: 7 | G8: 803 | H8: 11 | I8: 21 | J8: 11 | K8: 0.01369863 | L8: 0.0076660303 | M8: 0.024361896 | N8: 0.52380952 | O8: 0.32369534 | P8: 0.71655994 | Q8: 0 | R8: 7.9267643e-05 | S8: -0.0059657126 | T8: 0.010749166 | U8: 0 | V8: 1 | W8: =tFunnel[[#This Row],[reach_rate]] -tFunnel[[#This Row],[reach_rate_lower]] -> 0.0060325998 | X8: =tFunnel[[#This Row],[reach_rate_upper]]-tFunnel[[#This Row],[reach_rate]] -> 0.010663266 | Y8: =tFunnel[[#This Row],[step_conversion]]-tFunnel[[#This Row],[step_conversion_lower]] -> 0.20011418 | Z8: =tFunnel[[#This Row],[step_conversion_upper]]-tFunnel[[#This Row],[step_conversion]] -> 0.19275042 | AA8: =tFunnel[[#This Row],[gap_vs_rest]]-tFunnel[[#This Row],[gap_vs_rest_lower]] -> 0.0060449803 | AB8: =tFunnel[[#This Row],[gap_vs_rest_upper]]-tFunnel[[#This Row],[gap_vs_rest]] -> 0.010669898
A9: continent | B9: 3 | C9: africa | D9: 5 | E9: purchase | F9: 7 | G9: 3664 | H9: 43 | I9: 69 | J9: 43 | K9: 0.011735808 | L9: 0.0087246026 | M9: 0.015769765 | N9: 0.62318841 | O9: 0.50521886 | P9: 0.72816471 | Q9: 0 | R9: -0.0019033456 | S9: -0.0049395155 | T9: 0.0021482771 | U9: 0 | V9: 1 | W9: =tFunnel[[#This Row],[reach_rate]] -tFunnel[[#This Row],[reach_rate_lower]] -> 0.0030112052 | X9: =tFunnel[[#This Row],[reach_rate_upper]]-tFunnel[[#This Row],[reach_rate]] -> 0.0040339576 | Y9: =tFunnel[[#This Row],[step_conversion]]-tFunnel[[#This Row],[step_conversion_lower]] -> 0.11796954 | Z9: =tFunnel[[#This Row],[step_conversion_upper]]-tFunnel[[#This Row],[step_conversion]] -> 0.1049763 | AA9: =tFunnel[[#This Row],[gap_vs_rest]]-tFunnel[[#This Row],[gap_vs_rest_lower]] -> 0.0030361699 | AB9: =tFunnel[[#This Row],[gap_vs_rest_upper]]-tFunnel[[#This Row],[gap_vs_rest]] -> 0.0040516227
A10: continent | B10: 3 | C10: oceania | D10: 4 | E10: purchase | F10: 7 | G10: 3745 | H10: 51 | I10: 77 | J10: 51 | K10: 0.013618158 | L10: 0.010373166 | M10: 0.017859946 | N10: 0.66233766 | O10: 0.55124648 | P10: 0.75800078 | Q10: 0 | R10: -1.3986842e-06 | S10: -0.0032695428 | T10: 0.0042571721 | U10: 0 | V10: 1 | W10: =tFunnel[[#This Row],[reach_rate]] -tFunnel[[#This Row],[reach_rate_lower]] -> 0.0032449916 | X10: =tFunnel[[#This Row],[reach_rate_upper]]-tFunnel[[#This Row],[reach_rate]] -> 0.004241788 | Y10: =tFunnel[[#This Row],[step_conversion]]-tFunnel[[#This Row],[step_conversion_lower]] -> 0.11109118 | Z10: =tFunnel[[#This Row],[step_conversion_upper]]-tFunnel[[#This Row],[step_conversion]] -> 0.09566312 | AA10: =tFunnel[[#This Row],[gap_vs_rest]]-tFunnel[[#This Row],[gap_vs_rest_lower]] -> 0.0032681441 | AB10: =tFunnel[[#This Row],[gap_vs_rest_upper]]-tFunnel[[#This Row],[gap_vs_rest]] -> 0.0042585708
A11: continent | B11: 3 | C11: europe | D11: 3 | E11: purchase | F11: 7 | G11: 66291 | H11: 898 | I11: 1264 | J11: 897 | K11: 0.013546334 | L11: 0.012694121 | M11: 0.014454921 | N11: 0.7096519 | O11: 0.68402254 | P11: 0.7340108 | Q11: 0.0011135857 | R11: -8.9982911e-05 | S11: -0.001044135 | T11: 0.0009093936 | U11: 0 | V11: 0 | W11: =tFunnel[[#This Row],[reach_rate]] -tFunnel[[#This Row],[reach_rate_lower]] -> 0.00085221267 | X11: =tFunnel[[#This Row],[reach_rate_upper]]-tFunnel[[#This Row],[reach_rate]] -> 0.00090858785 | Y11: =tFunnel[[#This Row],[step_conversion]]-tFunnel[[#This Row],[step_conversion_lower]] -> 0.025629363 | Z11: =tFunnel[[#This Row],[step_conversion_upper]]-tFunnel[[#This Row],[step_conversion]] -> 0.024358906 | AA11: =tFunnel[[#This Row],[gap_vs_rest]]-tFunnel[[#This Row],[gap_vs_rest_lower]] -> 0.00095415204 | AB11: =tFunnel[[#This Row],[gap_vs_rest_upper]]-tFunnel[[#This Row],[gap_vs_rest]] -> 0.00099937651
A12: continent | B12: 3 | C12: asia | D12: 2 | E12: purchase | F12: 7 | G12: 84481 | H12: 1125 | I12: 1574 | J12: 1125 | K12: 0.013316604 | L12: 0.012565479 | M12: 0.014111987 | N12: 0.71473952 | O12: 0.69193078 | P12: 0.73650263 | Q12: 0 | R12: -0.00039733631 | S12: -0.0012702435 | T12: 0.00050728825 | U12: 0 | V12: 0 | W12: =tFunnel[[#This Row],[reach_rate]] -tFunnel[[#This Row],[reach_rate_lower]] -> 0.00075112505 | X12: =tFunnel[[#This Row],[reach_rate_upper]]-tFunnel[[#This Row],[reach_rate]] -> 0.00079538326 | Y12: =tFunnel[[#This Row],[step_conversion]]-tFunnel[[#This Row],[step_conversion_lower]] -> 0.022808736 | Z12: =tFunnel[[#This Row],[step_conversion_upper]]-tFunnel[[#This Row],[step_conversion]] -> 0.021763113 | AA12: =tFunnel[[#This Row],[gap_vs_rest]]-tFunnel[[#This Row],[gap_vs_rest_lower]] -> 0.0008729072 | AB12: =tFunnel[[#This Row],[gap_vs_rest_upper]]-tFunnel[[#This Row],[gap_vs_rest]] -> 0.00090462456
A13: continent | B13: 3 | C13: americas | D13: 1 | E13: purchase | F13: 7 | G13: 196608 | H13: 2715 | I13: 3781 | J13: 2713 | K13: 0.013809204 | L13: 0.013302784 | M13: 0.014334623 | N13: 0.71753504 | O13: 0.70296995 | P13: 0.73165856 | Q13: 0.00073664825 | R13: 0.00042420939 | S13: -0.0003433207 | T13: 0.0011871866 | U13: 0 | V13: 0 | W13: =tFunnel[[#This Row],[reach_rate]] -tFunnel[[#This Row],[reach_rate_lower]] -> 0.00050641986 | X13: =tFunnel[[#This Row],[reach_rate_upper]]-tFunnel[[#This Row],[reach_rate]] -> 0.00052541853 | Y13: =tFunnel[[#This Row],[step_conversion]]-tFunnel[[#This Row],[step_conversion_lower]] -> 0.014565095 | Z13: =tFunnel[[#This Row],[step_conversion_upper]]-tFunnel[[#This Row],[step_conversion]] -> 0.014123517 | AA13: =tFunnel[[#This Row],[gap_vs_rest]]-tFunnel[[#This Row],[gap_vs_rest_lower]] -> 0.00076753009 | AB13: =tFunnel[[#This Row],[gap_vs_rest_upper]]-tFunnel[[#This Row],[gap_vs_rest]] -> 0.00076297719
... A16: device_category | B16: 2 | C16: desktop | D16: 1 | E16: purchase | F16: 7 | G16: 206354 | H16: 2738 | I16: 3836 | J16: 2737 | K16: 0.013268461 | L16: 0.012783757 | M16: 0.013771287 | N16: 0.71350365 | O16: 0.69898803 | P16: 0.72759208 | Q16: 0.00036523009 | R16: -0.00083652567 | S16: -0.001616371 | T16: -6.443934e-05 | U16: 0 | V16: 0 | W16: =tFunnel[[#This Row],[reach_rate]] -tFunnel[[#This Row],[reach_rate_lower]] -> 0.00048470449 | X16: =tFunnel[[#This Row],[reach_rate_upper]]-tFunnel[[#This Row],[reach_rate]] -> 0.00050282601 | Y16: =tFunnel[[#This Row],[step_conversion]]-tFunnel[[#This Row],[step_conversion_lower]] -> 0.014515619 | Z16: =tFunnel[[#This Row],[step_conversion_upper]]-tFunnel[[#This Row],[step_conversion]] -> 0.014088431 | AA16: =tFunnel[[#This Row],[gap_vs_rest]]-tFunnel[[#This Row],[gap_vs_rest_lower]] -> 0.0007798453 | AB16: =tFunnel[[#This Row],[gap_vs_rest_upper]]-tFunnel[[#This Row],[gap_vs_rest]] -> 0.00077208633
A17: overall | B17: 1 | C17: all sessions | D17: 0 | E17: purchase | F17: 7 | G17: 355592 | H17: 4843 | I17: 6786 | J17: 4840 | K17: 0.013619541 | L17: 0.013243805 | M17: 0.014005787 | N17: 0.71323313 | O17: 0.70235463 | P17: 0.72387035 | Q17: 0.00061945075 | U17: 0 | V17: 0 | W17: =tFunnel[[#This Row],[reach_rate]] -tFunnel[[#This Row],[reach_rate_lower]] -> 0.00037573653 | X17: =tFunnel[[#This Row],[reach_rate_upper]]-tFunnel[[#This Row],[reach_rate]] -> 0.00038624515 | Y17: =tFunnel[[#This Row],[step_conversion]]-tFunnel[[#This Row],[step_conversion_lower]] -> 0.010878499 | Z17: =tFunnel[[#This Row],[step_conversion_upper]]-tFunnel[[#This Row],[step_conversion]] -> 0.010637219 | AA17: =tFunnel[[#This Row],[gap_vs_rest]]-tFunnel[[#This Row],[gap_vs_rest_lower]] -> 0 | AB17: =tFunnel[[#This Row],[gap_vs_rest_upper]]-tFunnel[[#This Row],[gap_vs_rest]] -> 0
A18: channel | B18: 4 | C18: cpc | D18: 6 | E18: add_payment_info | F18: 6 | G18: 15548 | H18: 214 | I18: 388 | J18: 213 | K18: 0.013763828 | L18: 0.012048877 | M18: 0.01571899 | N18: 0.54896907 | O18: 0.49921808 | P18: 0.59775991 | Q18: 0.0046728972 | R18: -0.0055630825 | S18: -0.0073407934 | T18: -0.0035551473 | U18: 0 | V18: 0 | W18: =tFunnel[[#This Row],[reach_rate]] -tFunnel[[#This Row],[reach_rate_lower]] -> 0.0017149515 | X18: =tFunnel[[#This Row],[reach_rate_upper]]-tFunnel[[#This Row],[reach_rate]] -> 0.0019551618 | Y18: =tFunnel[[#This Row],[step_conversion]]-tFunnel[[#This Row],[step_conversion_lower]] -> 0.049750987 | Z18: =tFunnel[[#This Row],[step_conversion_upper]]-tFunnel[[#This Row],[step_conversion]] -> 0.048790841 | AA18: =tFunnel[[#This Row],[gap_vs_rest]]-tFunnel[[#This Row],[gap_vs_rest_lower]] -> 0.0017777109 | AB18: =tFunnel[[#This Row],[gap_vs_rest_upper]]-tFunnel[[#This Row],[gap_vs_rest]] -> 0.0020079352
A19: channel | B19: 4 | C19: unknown | D19: 99 | E19: add_payment_info | F19: 6 | G19: 21651 | H19: 956 | I19: 1191 | J19: 956 | K19: 0.044155004 | L19: 0.041498434 | M19: 0.046973304 | N19: 0.80268682 | O19: 0.77912724 | P19: 0.8243001 | Q19: 0 | R19: 0.026696831 | S19: 0.024002451 | T19: 0.029549069 | U19: 0 | V19: 0 | W19: =tFunnel[[#This Row],[reach_rate]] -tFunnel[[#This Row],[reach_rate_lower]] -> 0.0026565707 | X19: =tFunnel[[#This Row],[reach_rate_upper]]-tFunnel[[#This Row],[reach_rate]] -> 0.0028182999 | Y19: =tFunnel[[#This Row],[step_conversion]]-tFunnel[[#This Row],[step_conversion_lower]] -> 0.023559577 | Z19: =tFunnel[[#This Row],[step_conversion_upper]]-tFunnel[[#This Row],[step_conversion]] -> 0.021613279 | AA19: =tFunnel[[#This Row],[gap_vs_rest]]-tFunnel[[#This Row],[gap_vs_rest_lower]] -> 0.0026943796 | AB19: =tFunnel[[#This Row],[gap_vs_rest_upper]]-tFunnel[[#This Row],[gap_vs_rest]] -> 0.0028522384
A20: channel | B20: 4 | C20: other | D20: 4 | E20: add_payment_info | F20: 6 | G20: 51789 | H20: 727 | I20: 1384 | J20: 727 | K20: 0.01403773 | L20: 0.013059941 | M20: 0.015087607 | N20: 0.52528902 | O20: 0.498947 | P20: 0.55149104 | Q20: 0 | R20: -0.0059061152 | S20: -0.0070058107 | T20: -0.0047470518 | U20: 0 | V20: 0 | W20: =tFunnel[[#This Row],[reach_rate]] -tFunnel[[#This Row],[reach_rate_lower]] -> 0.00097778939 | X20: =tFunnel[[#This Row],[reach_rate_upper]]-tFunnel[[#This Row],[reach_rate]] -> 0.0010498767 | Y20: =tFunnel[[#This Row],[step_conversion]]-tFunnel[[#This Row],[step_conversion_lower]] -> 0.026342021 | Z20: =tFunnel[[#This Row],[step_conversion_upper]]-tFunnel[[#This Row],[step_conversion]] -> 0.026202024 | AA20: =tFunnel[[#This Row],[gap_vs_rest]]-tFunnel[[#This Row],[gap_vs_rest_lower]] -> 0.0010996956 | AB20: =tFunnel[[#This Row],[gap_vs_rest_upper]]-tFunnel[[#This Row],[gap_vs_rest]] -> 0.0011590634
A21: channel | B21: 4 | C21: referral | D21: 3 | E21: add_payment_info | F21: 6 | G21: 62331 | H21: 1455 | I21: 2184 | J21: 1455 | K21: 0.02334312 | L21: 0.022186817 | M21: 0.024558171 | N21: 0.66620879 | O21: 0.64615499 | P21: 0.68567892 | Q21: 0 | R21: 0.0051647735 | S21: 0.0039089839 | T21: 0.0064701911 | U21: 0 | V21: 0 | W21: =tFunnel[[#This Row],[reach_rate]] -tFunnel[[#This Row],[reach_rate_lower]] -> 0.0011563026 | X21: =tFunnel[[#This Row],[reach_rate_upper]]-tFunnel[[#This Row],[reach_rate]] -> 0.0012150517 | Y21: =tFunnel[[#This Row],[step_conversion]]-tFunnel[[#This Row],[step_conversion_lower]] -> 0.020053799 | Z21: =tFunnel[[#This Row],[step_conversion_upper]]-tFunnel[[#This Row],[step_conversion]] -> 0.019470133 | AA21: =tFunnel[[#This Row],[gap_vs_rest]]-tFunnel[[#This Row],[gap_vs_rest_lower]] -> 0.0012557896 | AB21: =tFunnel[[#This Row],[gap_vs_rest_upper]]-tFunnel[[#This Row],[gap_vs_rest]] -> 0.0013054175
A22: channel | B22: 4 | C22: direct | D22: 2 | E22: add_payment_info | F22: 6 | G22: 82493 | H22: 1491 | I22: 2499 | J22: 1489 | K22: 0.018074261 | L22: 0.017187351 | M22: 0.019006052 | N22: 0.59583834 | O22: 0.57646537 | P22: 0.61491711 | Q22: 0.0013413816 | R22: -0.0013143125 | S22: -0.0023444214 | T22: -0.00025187874 | U22: 0 | V22: 0 | W22: =tFunnel[[#This Row],[reach_rate]] -tFunnel[[#This Row],[reach_rate_lower]] -> 0.00088690967 | X22: =tFunnel[[#This Row],[reach_rate_upper]]-tFunnel[[#This Row],[reach_rate]] -> 0.00093179134 | Y22: =tFunnel[[#This Row],[step_conversion]]-tFunnel[[#This Row],[step_conversion_lower]] -> 0.019372963 | Z22: =tFunnel[[#This Row],[step_conversion_upper]]-tFunnel[[#This Row],[step_conversion]] -> 0.01907877 | AA22: =tFunnel[[#This Row],[gap_vs_rest]]-tFunnel[[#This Row],[gap_vs_rest_lower]] -> 0.0010301089 | AB22: =tFunnel[[#This Row],[gap_vs_rest_upper]]-tFunnel[[#This Row],[gap_vs_rest]] -> 0.0010624338
A23: channel | B23: 4 | C23: organic | D23: 1 | E23: add_payment_info | F23: 6 | G23: 121780 | H23: 1943 | I23: 3416 | J23: 1943 | K23: 0.015955001 | L23: 0.015266369 | M23: 0.01667417 | N23: 0.56879391 | O23: 0.5521181 | P23: 0.58531517 | Q23: 0 | R23: -0.0047582218 | S23: -0.0056619298 | T23: -0.0038408925 | U23: 0 | V23: 0 | W23: =tFunnel[[#This Row],[reach_rate]] -tFunnel[[#This Row],[reach_rate_lower]] -> 0.00068863226 | X23: =tFunnel[[#This Row],[reach_rate_upper]]-tFunnel[[#This Row],[reach_rate]] -> 0.00071916897 | Y23: =tFunnel[[#This Row],[step_conversion]]-tFunnel[[#This Row],[step_conversion_lower]] -> 0.016675809 | Z23: =tFunnel[[#This Row],[step_conversion_upper]]-tFunnel[[#This Row],[step_conversion]] -> 0.016521259 | AA23: =tFunnel[[#This Row],[gap_vs_rest]]-tFunnel[[#This Row],[gap_vs_rest_lower]] -> 0.00090370803 | AB23: =tFunnel[[#This Row],[gap_vs_rest_upper]]-tFunnel[[#This Row],[gap_vs_rest]] -> 0.0009173293
A24: continent | B24: 3 | C24: unknown | D24: 99 | E24: add_payment_info | F24: 6 | G24: 803 | H24: 21 | I24: 29 | J24: 21 | K24: 0.02615193 | L24: 0.017167614 | M24: 0.03964833 | N24: 0.72413793 | O24: 0.54282867 | P24: 0.85301245 | Q24: 0 | R24: 0.0070842591 | S24: -0.001911584 | T24: 0.020587987 | U24: 0 | V24: 1 | W24: =tFunnel[[#This Row],[reach_rate]] -tFunnel[[#This Row],[reach_rate_lower]] -> 0.0089843161 | X24: =tFunnel[[#This Row],[reach_rate_upper]]-tFunnel[[#This Row],[reach_rate]] -> 0.013496399 | Y24: =tFunnel[[#This Row],[step_conversion]]-tFunnel[[#This Row],[step_conversion_lower]] -> 0.18130926 | Z24: =tFunnel[[#This Row],[step_conversion_upper]]-tFunnel[[#This Row],[step_conversion]] -> 0.12887452 | AA24: =tFunnel[[#This Row],[gap_vs_rest]]-tFunnel[[#This Row],[gap_vs_rest_lower]] -> 0.0089958431 | AB24: =tFunnel[[#This Row],[gap_vs_rest_upper]]-tFunnel[[#This Row],[gap_vs_rest]] -> 0.013503728
A25: continent | B25: 3 | C25: africa | D25: 5 | E25: add_payment_info | F25: 6 | G25: 3664 | H25: 69 | I25: 113 | J25: 69 | K25: 0.018831878 | L25: 0.014907976 | M25: 0.023763668 | N25: 0.61061947 | O25: 0.5184936 | P25: 0.69547155 | Q25: 0 | R25: -0.00025441265 | S25: -0.0042048762 | T25: 0.0046975788 | U25: 0 | V25: 0 | W25: =tFunnel[[#This Row],[reach_rate]] -tFunnel[[#This Row],[reach_rate_lower]] -> 0.0039239016 | X25: =tFunnel[[#This Row],[reach_rate_upper]]-tFunnel[[#This Row],[reach_rate]] -> 0.0049317901 | Y25: =tFunnel[[#This Row],[step_conversion]]-tFunnel[[#This Row],[step_conversion_lower]] -> 0.092125871 | Z25: =tFunnel[[#This Row],[step_conversion_upper]]-tFunnel[[#This Row],[step_conversion]] -> 0.08485208 | AA25: =tFunnel[[#This Row],[gap_vs_rest]]-tFunnel[[#This Row],[gap_vs_rest_lower]] -> 0.0039504636 | AB25: =tFunnel[[#This Row],[gap_vs_rest_upper]]-tFunnel[[#This Row],[gap_vs_rest]] -> 0.0049519914
A26: continent | B26: 3 | C26: oceania | D26: 4 | E26: add_payment_info | F26: 6 | G26: 3745 | H26: 77 | I26: 119 | J26: 77 | K26: 0.020560748 | L26: 0.016482909 | M26: 0.025621155 | N26: 0.64705882 | O26: 0.55782685 | P26: 0.72709325 | Q26: 0 | R26: 0.0014928005 | S26: -0.0026105862 | T26: 0.0065728833 | U26: 0 | V26: 0 | W26: =tFunnel[[#This Row],[reach_rate]] -tFunnel[[#This Row],[reach_rate_lower]] -> 0.0040778389 | X26: =tFunnel[[#This Row],[reach_rate_upper]]-tFunnel[[#This Row],[reach_rate]] -> 0.0050604071 | Y26: =tFunnel[[#This Row],[step_conversion]]-tFunnel[[#This Row],[step_conversion_lower]] -> 0.089231975 | Z26: =tFunnel[[#This Row],[step_conversion_upper]]-tFunnel[[#This Row],[step_conversion]] -> 0.080034422 | AA26: =tFunnel[[#This Row],[gap_vs_rest]]-tFunnel[[#This Row],[gap_vs_rest_lower]] -> 0.0041033868 | AB26: =tFunnel[[#This Row],[gap_vs_rest_upper]]-tFunnel[[#This Row],[gap_vs_rest]] -> 0.0050800828
A27: continent | B27: 3 | C27: europe | D27: 3 | E27: add_payment_info | F27: 6 | G27: 66291 | H27: 1264 | I27: 2066 | J27: 1263 | K27: 0.019067445 | L27: 0.018053884 | M27: 0.020136742 | N27: 0.61132623 | O27: 0.59011912 | P27: 0.63212013 | Q27: 0.00079113924 | R27: -1.9941441e-05 | S27: -0.0011523572 | T27: 0.0011572235 | U27: 0 | V27: 0 | W27: =tFunnel[[#This Row],[reach_rate]] -tFunnel[[#This Row],[reach_rate_lower]] -> 0.0010135612 | X27: =tFunnel[[#This Row],[reach_rate_upper]]-tFunnel[[#This Row],[reach_rate]] -> 0.0010692965 | Y27: =tFunnel[[#This Row],[step_conversion]]-tFunnel[[#This Row],[step_conversion_lower]] -> 0.021207116 | Z27: =tFunnel[[#This Row],[step_conversion_upper]]-tFunnel[[#This Row],[step_conversion]] -> 0.020793891 | AA27: =tFunnel[[#This Row],[gap_vs_rest]]-tFunnel[[#This Row],[gap_vs_rest_lower]] -> 0.0011324158 | AB27: =tFunnel[[#This Row],[gap_vs_rest_upper]]-tFunnel[[#This Row],[gap_vs_rest]] -> 0.001177165
A28: continent | B28: 3 | C28: asia | D28: 2 | E28: add_payment_info | F28: 6 | G28: 84481 | H28: 1574 | I28: 2531 | J28: 1574 | K28: 0.018631408 | L28: 0.017741237 | M28: 0.019565354 | N28: 0.62188858 | O28: 0.6028257 | P28: 0.64058202 | Q28: 0 | R28: -0.0005931898 | S28: -0.001626001 | T28: 0.0004709832 | U28: 0 | V28: 0 | W28: =tFunnel[[#This Row],[reach_rate]] -tFunnel[[#This Row],[reach_rate_lower]] -> 0.00089017107 | X28: =tFunnel[[#This Row],[reach_rate_upper]]-tFunnel[[#This Row],[reach_rate]] -> 0.00093394597 | Y28: =tFunnel[[#This Row],[step_conversion]]-tFunnel[[#This Row],[step_conversion_lower]] -> 0.019062878 | Z28: =tFunnel[[#This Row],[step_conversion_upper]]-tFunnel[[#This Row],[step_conversion]] -> 0.018693443 | AA28: =tFunnel[[#This Row],[gap_vs_rest]]-tFunnel[[#This Row],[gap_vs_rest_lower]] -> 0.0010328112 | AB28: =tFunnel[[#This Row],[gap_vs_rest_upper]]-tFunnel[[#This Row],[gap_vs_rest]] -> 0.001064173
A29: continent | B29: 3 | C29: americas | D29: 1 | E29: add_payment_info | F29: 6 | G29: 196608 | H29: 3781 | I29: 6204 | J29: 3779 | K29: 0.01923116 | L29: 0.018633424 | M29: 0.019847683 | N29: 0.60912315 | O29: 0.59691734 | P29: 0.6211939 | Q29: 0.00052896059 | R29: 0.0003298874 | S29: -0.000576304 | T29: 0.0012314784 | U29: 0 | V29: 0 | W29: =tFunnel[[#This Row],[reach_rate]] -tFunnel[[#This Row],[reach_rate_lower]] -> 0.00059773608 | X29: =tFunnel[[#This Row],[reach_rate_upper]]-tFunnel[[#This Row],[reach_rate]] -> 0.00061652288 | Y29: =tFunnel[[#This Row],[step_conversion]]-tFunnel[[#This Row],[step_conversion_lower]] -> 0.012205803 | Z29: =tFunnel[[#This Row],[step_conversion_upper]]-tFunnel[[#This Row],[step_conversion]] -> 0.012070751 | AA29: =tFunnel[[#This Row],[gap_vs_rest]]-tFunnel[[#This Row],[gap_vs_rest_lower]] -> 0.0009061914 | AB29: =tFunnel[[#This Row],[gap_vs_rest_upper]]-tFunnel[[#This Row],[gap_vs_rest]] -> 0.00090159096
... A32: device_category | B32: 2 | C32: desktop | D32: 1 | E32: add_payment_info | F32: 6 | G32: 206354 | H32: 3836 | I32: 6320 | J32: 3834 | K32: 0.018589414 | L32: 0.018015539 | M32: 0.019181213 | N32: 0.60664557 | O32: 0.59454087 | P32: 0.6186207 | Q32: 0.00052137643 | R32: -0.0011776691 | S32: -0.002097367 | T32: -0.0002656312 | U32: 0 | V32: 0 | W32: =tFunnel[[#This Row],[reach_rate]] -tFunnel[[#This Row],[reach_rate_lower]] -> 0.00057387537 | X32: =tFunnel[[#This Row],[reach_rate_upper]]-tFunnel[[#This Row],[reach_rate]] -> 0.00059179879 | Y32: =tFunnel[[#This Row],[step_conversion]]-tFunnel[[#This Row],[step_conversion_lower]] -> 0.012104698 | Z32: =tFunnel[[#This Row],[step_conversion_upper]]-tFunnel[[#This Row],[step_conversion]] -> 0.011975133 | AA32: =tFunnel[[#This Row],[gap_vs_rest]]-tFunnel[[#This Row],[gap_vs_rest_lower]] -> 0.00091969791 | AB32: =tFunnel[[#This Row],[gap_vs_rest_upper]]-tFunnel[[#This Row],[gap_vs_rest]] -> 0.00091203794
A33: overall | B33: 1 | C33: all sessions | D33: 0 | E33: add_payment_info | F33: 6 | G33: 355592 | H33: 6786 | I33: 11062 | J33: 6783 | K33: 0.019083669 | L33: 0.018639141 | M33: 0.019538588 | N33: 0.61318026 | O33: 0.60406677 | P33: 0.62221517 | Q33: 0.00044208665 | U33: 0 | V33: 0 | W33: =tFunnel[[#This Row],[reach_rate]] -tFunnel[[#This Row],[reach_rate_lower]] -> 0.0004445283 | X33: =tFunnel[[#This Row],[reach_rate_upper]]-tFunnel[[#This Row],[reach_rate]] -> 0.00045491886 | Y33: =tFunnel[[#This Row],[step_conversion]]-tFunnel[[#This Row],[step_conversion_lower]] -> 0.0091134899 | Z33: =tFunnel[[#This Row],[step_conversion_upper]]-tFunnel[[#This Row],[step_conversion]] -> 0.0090349098 | AA33: =tFunnel[[#This Row],[gap_vs_rest]]-tFunnel[[#This Row],[gap_vs_rest_lower]] -> 0 | AB33: =tFunnel[[#This Row],[gap_vs_rest_upper]]-tFunnel[[#This Row],[gap_vs_rest]] -> 0
A34: channel | B34: 4 | C34: cpc | D34: 6 | E34: add_shipping_info | F34: 5 | G34: 15548 | H34: 388 | I34: 389 | J34: 388 | K34: 0.024954978 | L34: 0.022617921 | M34: 0.027526717 | N34: 0.99742931 | O34: 0.98558417 | P34: 0.99954607 | Q34: 0 | R34: -0.0064350773 | S34: -0.008845798 | T34: -0.0037985704 | U34: 0 | V34: 0 | W34: =tFunnel[[#This Row],[reach_rate]] -tFunnel[[#This Row],[reach_rate_lower]] -> 0.0023370573 | X34: =tFunnel[[#This Row],[reach_rate_upper]]-tFunnel[[#This Row],[reach_rate]] -> 0.0025717389 | Y34: =tFunnel[[#This Row],[step_conversion]]-tFunnel[[#This Row],[step_conversion_lower]] -> 0.011845133 | Z34: =tFunnel[[#This Row],[step_conversion_upper]]-tFunnel[[#This Row],[step_conversion]] -> 0.0021167592 | AA34: =tFunnel[[#This Row],[gap_vs_rest]]-tFunnel[[#This Row],[gap_vs_rest_lower]] -> 0.0024107208 | AB34: =tFunnel[[#This Row],[gap_vs_rest_upper]]-tFunnel[[#This Row],[gap_vs_rest]] -> 0.0026365069
A35: channel | B35: 4 | C35: unknown | D35: 99 | E35: add_shipping_info | F35: 5 | G35: 21651 | H35: 1191 | I35: 1191 | J35: 1191 | K35: 0.055009007 | L35: 0.052050224 | M35: 0.058125668 | N35: 1 | O35: 0.99678496 | P35: 1 | Q35: 0 | R35: 0.025449893 | S35: 0.022434823 | T35: 0.028618077 | U35: 0 | V35: 0 | W35: =tFunnel[[#This Row],[reach_rate]] -tFunnel[[#This Row],[reach_rate_lower]] -> 0.0029587828 | X35: =tFunnel[[#This Row],[reach_rate_upper]]-tFunnel[[#This Row],[reach_rate]] -> 0.003116661 | Y35: =tFunnel[[#This Row],[step_conversion]]-tFunnel[[#This Row],[step_conversion_lower]] -> 0.0032150365 | Z35: =tFunnel[[#This Row],[step_conversion_upper]]-tFunnel[[#This Row],[step_conversion]] -> 0 | AA35: =tFunnel[[#This Row],[gap_vs_rest]]-tFunnel[[#This Row],[gap_vs_rest_lower]] -> 0.00301507 | AB35: =tFunnel[[#This Row],[gap_vs_rest_upper]]-tFunnel[[#This Row],[gap_vs_rest]] -> 0.0031681845
A36: channel | B36: 4 | C36: other | D36: 4 | E36: add_shipping_info | F36: 5 | G36: 51789 | H36: 1384 | I36: 1384 | J36: 1384 | K36: 0.026723822 | L36: 0.02536955 | M36: 0.028148299 | N36: 1 | O36: 0.99723206 | P36: 1 | Q36: 0 | R36: -0.0051323483 | S36: -0.006626164 | T36: -0.003579357 | U36: 0 | V36: 0 | W36: =tFunnel[[#This Row],[reach_rate]] -tFunnel[[#This Row],[reach_rate_lower]] -> 0.0013542714 | X36: =tFunnel[[#This Row],[reach_rate_upper]]-tFunnel[[#This Row],[reach_rate]] -> 0.0014244769 | Y36: =tFunnel[[#This Row],[step_conversion]]-tFunnel[[#This Row],[step_conversion_lower]] -> 0.0027679378 | Z36: =tFunnel[[#This Row],[step_conversion_upper]]-tFunnel[[#This Row],[step_conversion]] -> 0 | AA36: =tFunnel[[#This Row],[gap_vs_rest]]-tFunnel[[#This Row],[gap_vs_rest_lower]] -> 0.0014938157 | AB36: =tFunnel[[#This Row],[gap_vs_rest_upper]]-tFunnel[[#This Row],[gap_vs_rest]] -> 0.0015529913
A37: channel | B37: 4 | C37: referral | D37: 3 | E37: add_shipping_info | F37: 5 | G37: 62331 | H37: 2184 | I37: 2183 | J37: 2183 | K37: 0.035038745 | L37: 0.033623631 | M37: 0.036511167 | N37: 1 | O37: 0.99824338 | P37: 1 | Q37: 0.00045787546 | R37: 0.0047653705 | S37: 0.0032178565 | T37: 0.0063606807 | U37: 0 | V37: 0 | W37: =tFunnel[[#This Row],[reach_rate]] -tFunnel[[#This Row],[reach_rate_lower]] -> 0.0014151142 | X37: =tFunnel[[#This Row],[reach_rate_upper]]-tFunnel[[#This Row],[reach_rate]] -> 0.0014724218 | Y37: =tFunnel[[#This Row],[step_conversion]]-tFunnel[[#This Row],[step_conversion_lower]] -> 0.0017566243 | Z37: =tFunnel[[#This Row],[step_conversion_upper]]-tFunnel[[#This Row],[step_conversion]] -> 0 | AA37: =tFunnel[[#This Row],[gap_vs_rest]]-tFunnel[[#This Row],[gap_vs_rest_lower]] -> 0.001547514 | AB37: =tFunnel[[#This Row],[gap_vs_rest_upper]]-tFunnel[[#This Row],[gap_vs_rest]] -> 0.0015953102
A38: channel | B38: 4 | C38: direct | D38: 2 | E38: add_shipping_info | F38: 5 | G38: 82493 | H38: 2499 | I38: 2500 | J38: 2499 | K38: 0.030293479 | L38: 0.029145582 | M38: 0.03148512 | N38: 0.9996 | O38: 0.99773761 | P38: 0.99992939 | Q38: 0 | R38: -0.0010614505 | S38: -0.0023856791 | T38: 0.0002945312 | U38: 0 | V38: 0 | W38: =tFunnel[[#This Row],[reach_rate]] -tFunnel[[#This Row],[reach_rate_lower]] -> 0.0011478971 | X38: =tFunnel[[#This Row],[reach_rate_upper]]-tFunnel[[#This Row],[reach_rate]] -> 0.0011916408 | Y38: =tFunnel[[#This Row],[step_conversion]]-tFunnel[[#This Row],[step_conversion_lower]] -> 0.0018623854 | Z38: =tFunnel[[#This Row],[step_conversion_upper]]-tFunnel[[#This Row],[step_conversion]] -> 0.00032938669 | AA38: =tFunnel[[#This Row],[gap_vs_rest]]-tFunnel[[#This Row],[gap_vs_rest_lower]] -> 0.0013242286 | AB38: =tFunnel[[#This Row],[gap_vs_rest_upper]]-tFunnel[[#This Row],[gap_vs_rest]] -> 0.0013559817
A39: channel | B39: 4 | C39: organic | D39: 1 | E39: add_shipping_info | F39: 5 | G39: 121780 | H39: 3416 | I39: 3416 | J39: 3416 | K39: 0.028050583 | L39: 0.027137995 | M39: 0.028992944 | N39: 1 | O39: 0.99887671 | P39: 1 | Q39: 0 | R39: -0.0046509036 | S39: -0.0058186798 | T39: -0.003469045 | U39: 0 | V39: 0 | W39: =tFunnel[[#This Row],[reach_rate]] -tFunnel[[#This Row],[reach_rate_lower]] -> 0.0009125877 | X39: =tFunnel[[#This Row],[reach_rate_upper]]-tFunnel[[#This Row],[reach_rate]] -> 0.00094236135 | Y39: =tFunnel[[#This Row],[step_conversion]]-tFunnel[[#This Row],[step_conversion_lower]] -> 0.0011232857 | Z39: =tFunnel[[#This Row],[step_conversion_upper]]-tFunnel[[#This Row],[step_conversion]] -> 0 | AA39: =tFunnel[[#This Row],[gap_vs_rest]]-tFunnel[[#This Row],[gap_vs_rest_lower]] -> 0.0011677762 | AB39: =tFunnel[[#This Row],[gap_vs_rest_upper]]-tFunnel[[#This Row],[gap_vs_rest]] -> 0.0011818587
A40: continent | B40: 3 | C40: unknown | D40: 99 | E40: add_shipping_info | F40: 5 | G40: 803 | H40: 29 | I40: 29 | J40: 29 | K40: 0.03611457 | L40: 0.025261266 | M40: 0.051385092 | N40: 1 | O40: 0.8830302 | P40: 1 | Q40: 0 | R40: 0.0050172139 | S40: -0.0058513785 | T40: 0.020298225 | U40: 0 | V40: 1 | W40: =tFunnel[[#This Row],[reach_rate]] -tFunnel[[#This Row],[reach_rate_lower]] -> 0.010853305 | X40: =tFunnel[[#This Row],[reach_rate_upper]]-tFunnel[[#This Row],[reach_rate]] -> 0.015270521 | Y40: =tFunnel[[#This Row],[step_conversion]]-tFunnel[[#This Row],[step_conversion_lower]] -> 0.1169698 | Z40: =tFunnel[[#This Row],[step_conversion_upper]]-tFunnel[[#This Row],[step_conversion]] -> 0 | AA40: =tFunnel[[#This Row],[gap_vs_rest]]-tFunnel[[#This Row],[gap_vs_rest_lower]] -> 0.010868592 | AB40: =tFunnel[[#This Row],[gap_vs_rest_upper]]-tFunnel[[#This Row],[gap_vs_rest]] -> 0.015281011
A41: continent | B41: 3 | C41: africa | D41: 5 | E41: add_shipping_info | F41: 5 | G41: 3664 | H41: 113 | I41: 113 | J41: 113 | K41: 0.030840611 | L41: 0.02571542 | M41: 0.036948537 | N41: 1 | O41: 0.96712247 | P41: 1 | Q41: 0 | R41: -0.00027086599 | S41: -0.0054286308 | T41: 0.0058634605 | U41: 0 | V41: 0 | W41: =tFunnel[[#This Row],[reach_rate]] -tFunnel[[#This Row],[reach_rate_lower]] -> 0.0051251914 | X41: =tFunnel[[#This Row],[reach_rate_upper]]-tFunnel[[#This Row],[reach_rate]] -> 0.0061079255 | Y41: =tFunnel[[#This Row],[step_conversion]]-tFunnel[[#This Row],[step_conversion_lower]] -> 0.032877533 | Z41: =tFunnel[[#This Row],[step_conversion_upper]]-tFunnel[[#This Row],[step_conversion]] -> 0 | AA41: =tFunnel[[#This Row],[gap_vs_rest]]-tFunnel[[#This Row],[gap_vs_rest_lower]] -> 0.0051577649 | AB41: =tFunnel[[#This Row],[gap_vs_rest_upper]]-tFunnel[[#This Row],[gap_vs_rest]] -> 0.0061343265
A42: continent | B42: 3 | C42: oceania | D42: 4 | E42: add_shipping_info | F42: 5 | G42: 3745 | H42: 119 | I42: 119 | J42: 119 | K42: 0.031775701 | L42: 0.02662022 | M42: 0.037890766 | N42: 1 | O42: 0.96872832 | P42: 1 | Q42: 0 | R42: 0.00067411417 | S42: -0.0045137475 | T42: 0.0068155472 | U42: 0 | V42: 0 | W42: =tFunnel[[#This Row],[reach_rate]] -tFunnel[[#This Row],[reach_rate_lower]] -> 0.0051554807 | X42: =tFunnel[[#This Row],[reach_rate_upper]]-tFunnel[[#This Row],[reach_rate]] -> 0.0061150648 | Y42: =tFunnel[[#This Row],[step_conversion]]-tFunnel[[#This Row],[step_conversion_lower]] -> 0.031271681 | Z42: =tFunnel[[#This Row],[step_conversion_upper]]-tFunnel[[#This Row],[step_conversion]] -> 0 | AA42: =tFunnel[[#This Row],[gap_vs_rest]]-tFunnel[[#This Row],[gap_vs_rest_lower]] -> 0.0051878617 | AB42: =tFunnel[[#This Row],[gap_vs_rest_upper]]-tFunnel[[#This Row],[gap_vs_rest]] -> 0.006141433
A43: continent | B43: 3 | C43: europe | D43: 3 | E43: add_shipping_info | F43: 5 | G43: 66291 | H43: 2066 | I43: 2066 | J43: 2066 | K43: 0.031165618 | L43: 0.029869777 | M43: 0.032515793 | N43: 1 | O43: 0.99814408 | P43: 1 | Q43: 0 | R43: 6.9977387e-05 | S43: -0.0013747423 | T43: 0.0015583417 | U43: 0 | V43: 0 | W43: =tFunnel[[#This Row],[reach_rate]] -tFunnel[[#This Row],[reach_rate_lower]] -> 0.0012958413 | X43: =tFunnel[[#This Row],[reach_rate_upper]]-tFunnel[[#This Row],[reach_rate]] -> 0.0013501746 | Y43: =tFunnel[[#This Row],[step_conversion]]-tFunnel[[#This Row],[step_conversion_lower]] -> 0.0018559194 | Z43: =tFunnel[[#This Row],[step_conversion_upper]]-tFunnel[[#This Row],[step_conversion]] -> 0 | AA43: =tFunnel[[#This Row],[gap_vs_rest]]-tFunnel[[#This Row],[gap_vs_rest_lower]] -> 0.0014447196 | AB43: =tFunnel[[#This Row],[gap_vs_rest_upper]]-tFunnel[[#This Row],[gap_vs_rest]] -> 0.0014883644
A44: continent | B44: 3 | C44: asia | D44: 2 | E44: add_shipping_info | F44: 5 | G44: 84481 | H44: 2531 | I44: 2531 | J44: 2531 | K44: 0.029959399 | L44: 0.028831043 | M44: 0.0311305 | N44: 1 | O44: 0.99848454 | P44: 1 | Q44: 0 | R44: -0.001507417 | S44: -0.0028165497 | T44: -0.00016776519 | U44: 0 | V44: 0 | W44: =tFunnel[[#This Row],[reach_rate]] -tFunnel[[#This Row],[reach_rate_lower]] -> 0.001128356 | X44: =tFunnel[[#This Row],[reach_rate_upper]]-tFunnel[[#This Row],[reach_rate]] -> 0.0011711008 | Y44: =tFunnel[[#This Row],[step_conversion]]-tFunnel[[#This Row],[step_conversion_lower]] -> 0.0015154632 | Z44: =tFunnel[[#This Row],[step_conversion_upper]]-tFunnel[[#This Row],[step_conversion]] -> 0 | AA44: =tFunnel[[#This Row],[gap_vs_rest]]-tFunnel[[#This Row],[gap_vs_rest_lower]] -> 0.0013091327 | AB44: =tFunnel[[#This Row],[gap_vs_rest_upper]]-tFunnel[[#This Row],[gap_vs_rest]] -> 0.0013396518
...

Sheet calc
A1: step_sort | B1: step | C1: label | D1: sessions_reached | E1: reach_rate | F1: reach_rate_lower | G1: reach_rate_upper | H1: step_conversion | I1: step_conversion_lower | J1: step_conversion_upper | K1: skipped_prev_share | L1: conv_err_minus | M1: conv_err_plus | N1: bar_label | P1: steps | R1: segment_type | S1: segment_value | T1: segment_sessions | U1: reach_rate | V1: reach_rate_lower | W1: reach_rate_upper | X1: gap_vs_rest | Y1: gap_vs_rest_lower | Z1: gap_vs_rest_upper | AA1: is_thin_segment | AB1: gap_err_minus | AC1: gap_err_plus | AD1: group | AE1: segment | AF1: differs | AG1: within_noise | AI1: week_label | AJ1: sessions | AK1: conversion | AL1: cr_err_minus | AM1: cr_err_plus | AO1: category | AP1: sessions_viewed | AQ1: view_to_purchase | AR1: v2p_err_minus | AS1: v2p_err_plus | AT1: is_thin | AU1: label | AV1: highlight | AW1: others
